#VRML_SIM R2023a utf8

EXTERNPROTO "https://raw.githubusercontent.com/cyberbotics/webots/R2023a/projects/objects/trees/protos/BigSassafras.proto"
EXTERNPROTO "https://raw.githubusercontent.com/cyberbotics/webots/R2023a/projects/objects/trees/protos/Cypress.proto"
EXTERNPROTO "https://raw.githubusercontent.com/cyberbotics/webots/R2023a/projects/appearances/protos/DryMud.proto"
EXTERNPROTO "https://raw.githubusercontent.com/cyberbotics/webots/R2023a/projects/objects/trees/protos/Oak.proto"
EXTERNPROTO "https://raw.githubusercontent.com/cyberbotics/webots/R2023a/projects/appearances/protos/PaintedWood.proto"
EXTERNPROTO "https://raw.githubusercontent.com/cyberbotics/webots/R2023a/projects/objects/trees/protos/Pine.proto"
EXTERNPROTO "https://raw.githubusercontent.com/cyberbotics/webots/R2023a/projects/appearances/protos/Rubber.proto"
EXTERNPROTO "https://raw.githubusercontent.com/cyberbotics/webots/R2023a/projects/objects/trees/protos/SimpleTree.proto"
EXTERNPROTO "https://raw.githubusercontent.com/cyberbotics/webots/R2023a/projects/objects/backgrounds/protos/TexturedBackground.proto"
EXTERNPROTO "https://raw.githubusercontent.com/cyberbotics/webots/R2023a/projects/objects/backgrounds/protos/TexturedBackgroundLight.proto"
EXTERNPROTO "https://raw.githubusercontent.com/cyberbotics/webots/R2023a/projects/objects/floors/protos/UnevenTerrain.proto"

WorldInfo {
}
Viewpoint {
  orientation -0.06483257775608153 -0.9509027732109036 0.30262295478253887 5.840034798698183
  position -51.51501536266538 9.725365242713433 33.92962971847854
}
TexturedBackground {
}
TexturedBackgroundLight {
}
Robot {
  translation 19.43619285504855 3.0434314248874146 4.516409998496692
  rotation 0.023222444461454755 0.24565245014573223 -0.9690797654530989 0.17858143287039144
  children [
    DEF base Shape {
      appearance PaintedWood {
        colorOverride 0 0.2 0.1
      }
      geometry DEF Base Box {
        size 1.2 3 1
      }
    }
    DistanceSensor {
      translation 0.35 -1.5 0
      rotation 0 0 1 -1.5707853071795865
      children [
        DEF ds Shape {
          appearance PBRAppearance {
            baseColor 1 1 0
            metalness 0
          }
          geometry Sphere {
            radius 0.1
          }
        }
      ]
      name "ds_right"
      boundingObject DEF ds Shape {
        appearance PBRAppearance {
          baseColor 1 1 0
          metalness 0
        }
        geometry Sphere {
          radius 0.1
        }
      }
      physics DEF phy2 Physics {
        mass 1
      }
      lookupTable [
        0 0 0
        3 1000 0
      ]
      numberOfRays 2
    }
    DistanceSensor {
      translation -0.35 -1.5 0
      rotation 0 0 -1 1.57079
      children [
        DEF ds Shape {
          appearance PBRAppearance {
            baseColor 1 1 0
            metalness 0
          }
          geometry Sphere {
            radius 0.1
          }
        }
      ]
      name "ds_left"
      lookupTable [
        0 0 0
        3 1000 0
      ]
      numberOfRays 2
    }
    DEF wheel1 HingeJoint {
      jointParameters HingeJointParameters {
        position 547.1894027700878
        anchor 0.75 -0.96 -0.53
      }
      device [
        RotationalMotor {
          name "wheel1"
          maxTorque 50
        }
      ]
      endPoint Solid {
        translation 0.7499990499236211 -0.9599980615096066 -0.5300155460258651
        rotation 0.2630419973118669 0.9282333014483605 0.2630434293656873 1.6452089977677669
        children [
          DEF wheel Shape {
            appearance Rubber {
            }
            geometry Cylinder {
              height 0.5
              radius 0.5
            }
          }
        ]
        boundingObject USE wheel
        physics DEF phy1 Physics {
          mass 1
        }
        linearVelocity 0.36145405256082985 -0.09333954952108 -0.009701103307591512
        angularVelocity -3.91231287895163 0.7035057447290096 0.5172500726278435
      }
    }
    DEF wheel2 HingeJoint {
      jointParameters HingeJointParameters {
        position 589.4948369520524
        anchor -0.75 -0.96 -0.53
      }
      device [
        RotationalMotor {
          name "wheel2"
          maxTorque 50
        }
      ]
      endPoint Solid {
        translation -0.7499985356674741 -0.9599815680949222 -0.5300148240213811
        rotation 0.4704379595966417 -0.746568457463151 0.4704504910100955 4.424188374272253
        children [
          DEF wheel Shape {
            appearance Rubber {
            }
            geometry Cylinder {
              height 0.5
              radius 0.5
            }
          }
        ]
        name "solid(1)"
        boundingObject USE wheel
        physics USE phy1
        linearVelocity 0.27516998987738756 -0.5786138503480427 -0.01859386737755548
        angularVelocity 3.951459307743637 -0.7230585879998639 0.1645277968292317
      }
    }
    DEF wheel3 HingeJoint {
      jointParameters HingeJointParameters {
        position 530.2033657643525
        anchor 0.75 0.96 -0.53
      }
      device [
        RotationalMotor {
          name "wheel3"
          maxTorque 50
        }
      ]
      endPoint Solid {
        translation 0.750001387583962 0.9600165592060206 -0.5299835446435259
        rotation 0.6829128631456953 0.2593152318312677 0.682924323692197 2.63414979896295
        children [
          DEF wheel Shape {
            appearance Rubber {
            }
            geometry Cylinder {
              height 0.5
              radius 0.5
            }
          }
        ]
        name "solid(2)"
        boundingObject USE wheel
        physics USE phy1
        linearVelocity -0.25880891528817584 0.016623761127611235 0.029283885360557402
        angularVelocity -3.91246543675763 0.7035046546255415 0.5172484124182843
      }
    }
    DEF wheel4 HingeJoint {
      jointParameters HingeJointParameters {
        position 580.9608761115613
        anchor -0.75 0.96 -0.53
      }
      device [
        RotationalMotor {
          name "wheel4"
          maxTorque 50
        }
      ]
      endPoint Solid {
        translation -0.7500009508139986 0.9600030293937483 -0.5300153710887856
        rotation 0.7046789801791719 0.08274217616961468 0.7046852255981808 2.976487286254909
        children [
          DEF wheel Shape {
            appearance Rubber {
            }
            geometry Cylinder {
              height 0.5
              radius 0.5
            }
          }
        ]
        name "solid(3)"
        boundingObject USE wheel
        physics USE phy1
        linearVelocity -0.3451626405810922 -0.4687875491851989 0.020405640485625858
        angularVelocity 3.951392684046387 -0.7230570854069589 0.1645958269646589
      }
    }
  ]
  boundingObject USE base
  physics USE phy1
  controller "my_controller"
  linearVelocity 0.2569156262473029 -0.2698774581146789 -0.008733058896444858
  angularVelocity 0.018986418058687483 -0.009421229881643456 0.32786422922581115
}
DEF forest Solid {
  children [
    Pine {
      translation -15.62 20.85 1.15
      name "pine tree(6)"
    }
    Pine {
      translation -15.62 -10.45 1.15
      name "pine tree(5)"
    }
    Pine {
      translation 11.67 -10.45 1.45
      name "pine tree(3)"
    }
    Pine {
      translation 20.49 -10.45 2.81
      name "pine tree(4)"
    }
    Pine {
      translation 11.67 15.84 1.88
      name "pine tree(2)"
    }
    Pine {
      translation -4.35 9.25 2.22
      name "pine tree(1)"
    }
    Pine {
      translation -4.35 -3.53 2.18
    }
    SimpleTree {
      translation 0 0 3
    }
    SimpleTree {
      translation 6 0 3
      name "tree(1)"
    }
    SimpleTree {
      translation 6 10 3
      name "tree(2)"
    }
    SimpleTree {
      translation 16 15 3
      name "tree(3)"
    }
    SimpleTree {
      translation -16 -15 1.8
      name "tree(4)"
    }
    SimpleTree {
      translation 16 -15 3
      name "tree(5)"
    }
    SimpleTree {
      translation 5 -22 2
      name "tree(6)"
    }
    SimpleTree {
      translation -15 -22 2
      name "tree(7)"
    }
    SimpleTree {
      translation -9 22 2
      name "tree(8)"
    }
    SimpleTree {
      translation -18 16 2.5
      name "tree(9)"
    }
    SimpleTree {
      translation -22 -3 2
      name "tree(10)"
    }
    SimpleTree {
      translation 10 -8 3
      name "tree(11)"
    }
    SimpleTree {
      translation -5 -8 2.3
      name "tree(12)"
    }
    SimpleTree {
      translation 1 -17 2
      name "tree(13)"
    }
    Oak {
      translation 14.94 0 3.24
    }
    Oak {
      translation 20 -5.97 3.28
      name "oak tree(1)"
    }
    Oak {
      translation 15.97 -10.75 3.02
      name "oak tree(2)"
    }
    Oak {
      translation 15.97 11.04 3.07
      name "oak tree(3)"
    }
    Oak {
      translation -24.52 6.27 2.46
      name "oak tree(4)"
    }
    Oak {
      translation -12.06 2.39 2.09
      name "oak tree(6)"
    }
    Oak {
      translation -13.84 10.96 2.09
      name "oak tree(7)"
    }
    Oak {
      translation -2.97 18.97 1.79
      name "oak tree(8)"
    }
    Oak {
      translation 0.35 13.07 2.24
      name "oak tree(9)"
    }
    Oak {
      translation -9.22 15.64 2.72
      name "oak tree(5)"
    }
    Oak {
      translation 7.46 20.45 2.43
      name "oak tree(10)"
    }
    Oak {
      translation 16.74 21.4 2.43
      name "oak tree(11)"
    }
    BigSassafras {
      translation -11.82 -13.71 1.72
    }
    BigSassafras {
      translation -21.32 -8.95 1.72
      name "sassafras tree(1)"
    }
    BigSassafras {
      translation 19.67 7.95 3.44
      name "sassafras tree(2)"
    }
    BigSassafras {
      translation 19.67 -1.13 2.97
      name "sassafras tree(3)"
    }
    BigSassafras {
      translation 21.66 -19.93 2.97
      name "sassafras tree(4)"
    }
    BigSassafras {
      translation 9.84 -19.93 2.64
      name "sassafras tree(5)"
    }
    BigSassafras {
      translation -6.69 -19.93 1.29
      name "sassafras tree(6)"
    }
    BigSassafras {
      translation -16.82 -5.16 2.98
      name "sassafras tree(7)"
    }
    BigSassafras {
      translation -16.82 8.12 2.98
      name "sassafras tree(8)"
    }
    BigSassafras {
      translation -21.82 21.14 2.98
      name "sassafras tree(9)"
    }
    BigSassafras {
      translation 1.95 21.14 2.63
      name "sassafras tree(10)"
    }
    Cypress {
      translation -11.36 0 1.96
    }
    Cypress {
      translation -14.16 5.78 2.06
      name "cypress tree(1)"
    }
    Cypress {
      translation 20.42 15.8 3.01
      name "cypress tree(2)"
    }
    Cypress {
      translation 21.87 20.79 3.01
      name "cypress tree(3)"
    }
    Cypress {
      translation 11.51 1.81 3.01
      name "cypress tree(4)"
    }
    Cypress {
      translation 2.77 -10.75 2.51
      name "cypress tree(5)"
    }
    Cypress {
      translation -2.24 -21.57 1.87
      name "cypress tree(6)"
    }
    Cypress {
      translation 15.22 -21.57 2.5
      name "cypress tree(7)"
    }
    Cypress {
      translation 6.61 -15.53 2.8
      name "cypress tree(8)"
    }
    Cypress {
      translation -11.26 5.51 2.26
      name "cypress tree(9)"
    }
  ]
}
UnevenTerrain {
}
DEF Border Solid {
  translation 0 0 3.9
  children [
    Solid {
      translation -1.3792605043011323e-07 -25.200000625478946 -0.37009417837608183
      rotation -0.030209004771724574 -0.10649179531902823 0.99385457364769 1.1643902338565348e-05
      children [
        DEF border Shape {
          appearance DryMud {
          }
          geometry Box {
            size 49 1 3
          }
        }
      ]
      name "border1"
      boundingObject USE border
      physics DEF phy1 Physics {
        mass 1
      }
      linearVelocity 0 0 -1.2139210974737436e-07
    }
    Solid {
      translation 0 25.53 -0.3700940983012595
      children [
        DEF border Shape {
          appearance DryMud {
          }
          geometry Box {
            size 49 1 3
          }
        }
      ]
      name "border2"
      boundingObject USE border
      physics USE phy1
      linearVelocity 0 0 -1.2139210974737436e-07
    }
    Solid {
      translation 25.53 0 -0.37
      rotation 0 0 1 1.5708
      children [
        DEF border Shape {
          appearance DryMud {
          }
          geometry Box {
            size 49 1 3
          }
        }
      ]
      name "border3"
      boundingObject USE border
    }
    Solid {
      translation -25.5301 1.57462e-05 -0.3700940983012595
      rotation 5.1580022398749126e-05 -9.550089548459884e-05 0.9999999941095401 1.569814080916819
      children [
        DEF border Shape {
          appearance DryMud {
          }
          geometry Box {
            size 49 1 3
          }
        }
      ]
      name "border4"
      boundingObject USE border
      physics USE phy1
      linearVelocity 0 0 -1.2139210974737436e-07
    }
  ]
  name "solid(1)"
}
